<?xml version="1.0"?>

<robot name="BoxAtlas">
  <link name="root">
  </link>

  <link name="floor">
    <visual>
      <origin xyz="0 0.5 -0.05"/>
      <geometry>
        <box size="1 3 0.1"/>
      </geometry>
    </visual>
    <collision>
      <origin xyz="0 0.5 -0.05"/>
      <geometry>
        <box size="1 3 0.1"/>
      </geometry>
    </collision>
    <collision>
      <geometry>
        <plane normal="0 0 1"/>
      </geometry>
    </collision>
  </link>

  <joint name="root_to_floor" type="fixed">
    <parent link="root"/>
    <child link="floor"/>
  </joint>

  <link name="wall">
    <visual>
      <origin xyz="0 1.05 1"/>
      <geometry>
        <box size="1 0.1 2.2"/>
      </geometry>
    </visual>
    <collision>
      <origin xyz="0 1.05 1"/>
      <geometry>
        <box size="1 0.1 2.2"/>
      </geometry>
    </collision>
    <collision>
      <origin xyz="0 1 1"/>
      <geometry>
        <plane normal="0 -1 0"/>
      </geometry>
    </collision>
  </link>

  <joint name="floor_to_wall" type="fixed">
    <parent link="floor"/>
    <child link="wall"/>
  </joint>

  <link name="floating_base_dummy">
    <inertial>
      <mass value="0.0"/>
      <origin rpy="0 0 0" xyz="0 0 0"/>
      <inertia ixx="0.0" iyy="0.0" izz="0.0" ixy="0.0" ixz="0.0" iyz="0.0"/>
    </inertial>
  </link>

  <joint name="floating_base" type="planar">
    <axis xyz="0 -1 0"/>
    <origin rpy="0 0 1.5707963267948966"/>
    <parent link="root"/>
    <child link="floating_base_dummy"/>
  </joint>

  <link name="pelvis">
    <inertial>
      <mass value="1.0"/>
      <origin rpy="0 0 0.3" xyz="0 0 0"/>
      <inertia ixx="0.039" iyy="0.025" izz="0.014" ixy="0.0" ixz="0.0" iyz="0.0"/>
    </inertial>
    <visual>
      <origin xyz="0 0 0.3"/>
      <geometry>
        <box size="0.05 0.4 0.55"/>
      </geometry>
    </visual>
  </link>

  <joint name="floating_base_dummy_to_pelvis" type="fixed">
    <origin rpy="0 0 -1.5707963267948966"/>
    <parent link="floating_base_dummy"/>
    <child link="pelvis"/>
  </joint>

  <link name="r_hand_mount_dummy">
    <inertial>
      <mass value="0.0"/>
      <origin rpy="0 0 0" xyz="0 0 0"/>
      <inertia ixx="0.0" iyy="0.0" izz="0.0" ixy="0.0" ixz="0.0" iyz="0.0"/>
    </inertial>
    <visual>
      <geometry>
        <sphere radius="0.05"/>
      </geometry>
    </visual>
    <visual>
      <origin xyz="0 0 0.2"/>
      <geometry>
        <cylinder radius="0.03" length="0.4"/>
      </geometry>
    </visual>
  </link>

  <link name="r_hand_mount">
    <inertial>
      <mass value="0.05"/>
      <origin rpy="0 0 0" xyz="0 0 0"/>
      <inertia ixx="0.039" iyy="0.025" izz="0.014" ixy="0.0" ixz="0.0" iyz="0.0"/>
    </inertial>
    <visual>
      <geometry>
        <sphere radius="0.025"/>
      </geometry>
    </visual>
    <visual>
      <origin xyz="0 0 -0.2"/>
      <geometry>
        <cylinder radius="0.02" length="0.4"/>
      </geometry>
    </visual>
    <collision>
      <geometry>
        <sphere radius="0"/>
      </geometry>
    </collision>
  </link>

  <joint name="pelvis_to_r_hand_mount_rotation" type="revolute">
    <parent link="pelvis"/>
    <child link="r_hand_mount_dummy"/>
    <origin xyz="0 -0.3 0.45" rpy="-3.1415926535897 0 0"/>
    <axis xyz="-1 0 0"/>
    <limit lower="0" upper="1.6708" velocity="100" effort="2"/>
  </joint>

  <joint name="pelvis_to_r_hand_mount_extension" type="prismatic">
    <parent link="r_hand_mount_dummy"/>
    <child link="r_hand_mount"/>
    <origin xyz="0 0 0"/>
    <axis xyz="0 0 1"/>
    <limit lower="0.375" upper="0.75" velocity="100" effort="2"/>
  </joint>

  <link name="l_hand_mount_dummy">
    <inertial>
      <mass value="0.0"/>
      <origin rpy="0 0 0" xyz="0 0 0"/>
      <inertia ixx="0.0" iyy="0.0" izz="0.0" ixy="0.0" ixz="0.0" iyz="0.0"/>
    </inertial>
    <visual>
      <geometry>
        <sphere radius="0.05"/>
      </geometry>
    </visual>
    <visual>
      <origin xyz="0 0 0.2"/>
      <geometry>
        <cylinder radius="0.03" length="0.4"/>
      </geometry>
    </visual>
  </link>

  <link name="l_hand_mount">
    <inertial>
      <mass value="0.05"/>
      <origin rpy="0 0 0" xyz="0 0 0"/>
      <inertia ixx="0.039" iyy="0.025" izz="0.014" ixy="0.0" ixz="0.0" iyz="0.0"/>
    </inertial>
    <visual>
      <geometry>
        <sphere radius="0.025"/>
      </geometry>
    </visual>
    <visual>
      <origin xyz="0 0 -0.2"/>
      <geometry>
        <cylinder radius="0.02" length="0.4"/>
      </geometry>
    </visual>
    <collision>
      <geometry>
        <sphere radius="0"/>
      </geometry>
    </collision>
  </link>

  <joint name="pelvis_to_l_hand_mount_rotation" type="revolute">
    <parent link="pelvis"/>
    <child link="l_hand_mount_dummy"/>
    <origin xyz="0 0.3 0.45" rpy="3.1415926535897 0 0"/>
    <axis xyz="1 0 0"/>
    <limit lower="0" upper="1.6708" velocity="100" effort="2"/>
  </joint>

  <joint name="pelvis_to_l_hand_mount_extension" type="prismatic">
    <parent link="l_hand_mount_dummy"/>
    <child link="l_hand_mount"/>
    <origin xyz="0 0 0"/>
    <axis xyz="0 0 1"/>
    <limit lower="0.375" upper="0.75" velocity="100" effort="2"/>
  </joint>

  <link name="r_foot_sole_dummy">
    <inertial>
      <mass value="0.0"/>
      <origin rpy="0 0 0" xyz="0 0 0"/>
      <inertia ixx="0.0" iyy="0.0" izz="0.0" ixy="0.0" ixz="0.0" iyz="0.0"/>
    </inertial>
    <visual>
      <geometry>
        <sphere radius="0.05"/>
      </geometry>
    </visual>
    <visual>
      <origin xyz="0 0 0.2375" rpy="0 0 0"/>
      <geometry>
        <cylinder radius="0.03" length="0.475"/>
      </geometry>
    </visual>
  </link>

  <link name="r_foot_sole">
    <inertial>
      <mass value="0.2"/>
      <origin rpy="0 0 0" xyz="0 0 0"/>
      <inertia ixx="0.039" iyy="0.025" izz="0.014" ixy="0.0" ixz="0.0" iyz="0.0"/>
    </inertial>
    <visual>
      <geometry>
        <sphere radius="0.025"/>
      </geometry>
    </visual>
    <visual>
      <origin xyz="0 0 -0.2375" rpy="0 0 0"/>
      <geometry>
        <cylinder radius="0.02" length="0.475"/>
      </geometry>
    </visual>
    <collision>
      <geometry>
        <sphere radius="0"/>
      </geometry>
    </collision>
  </link>

  <joint name="pelvis_to_r_foot_sole_rotation" type="revolute">
    <parent link="pelvis"/>
    <child link="r_foot_sole_dummy"/>
    <origin xyz="0 -0.11 0" rpy="3.1415926535897 0 0"/>
    <axis xyz="-1 0 0"/>
    <limit lower="-0.05" upper="0.785398" velocity="100" effort="10"/>
  </joint>

  <joint name="pelvis_to_r_foot_sole_extension" type="prismatic">
    <parent link="r_foot_sole_dummy"/>
    <child link="r_foot_sole"/>
    <origin xyz="0 0 0"/>
    <axis xyz="0 0 1"/>
    <limit lower="0.45" upper="0.9" velocity="100" effort="20"/>
  </joint>

  <link name="l_foot_sole_dummy">
    <inertial>
      <mass value="0.0"/>
      <origin rpy="0 0 0" xyz="0 0 0"/>
      <inertia ixx="0.0" iyy="0.0" izz="0.0" ixy="0.0" ixz="0.0" iyz="0.0"/>
    </inertial>
    <visual>
      <geometry>
        <sphere radius="0.05"/>
      </geometry>
    </visual>
    <visual>
      <origin xyz="0 0 0.2375" rpy="0 0 0"/>
      <geometry>
        <cylinder radius="0.03" length="0.475"/>
      </geometry>
    </visual>
  </link>

  <link name="l_foot_sole">
    <inertial>
      <mass value="0.2"/>
      <origin rpy="0 0 0" xyz="0 0 0"/>
      <inertia ixx="0.039" iyy="0.025" izz="0.014" ixy="0.0" ixz="0.0" iyz="0.0"/>
    </inertial>
    <visual>
      <geometry>
        <sphere radius="0.025"/>
      </geometry>
    </visual>
    <visual>
      <origin xyz="0 0 -0.2375" rpy="0 0 0"/>
      <geometry>
        <cylinder radius="0.02" length="0.475"/>
      </geometry>
    </visual>
    <collision>
      <geometry>
        <sphere radius="0"/>
      </geometry>
    </collision>
  </link>

  <joint name="pelvis_to_l_foot_sole_rotation" type="revolute">
    <parent link="pelvis"/>
    <child link="l_foot_sole_dummy"/>
    <origin xyz="0 0.11 0" rpy="3.1415926535897 0 0"/>
    <axis xyz="1 0 0"/>
    <limit lower="-0.05" upper="0.785398" velocity="100" effort="10"/>
  </joint>

  <joint name="pelvis_to_l_foot_sole_extension" type="prismatic">
    <parent link="l_foot_sole_dummy"/>
    <child link="l_foot_sole"/>
    <origin xyz="0 0 0"/>
    <axis xyz="0 0 1"/>
    <limit lower="0.45" upper="0.9" velocity="100" effort="20"/>
  </joint>


</robot>


